Workbook
Name alpha: #REF!
Name codes: 'Calc transition matrix'!$O$2:$P$5
Name ewp_baseline: #REF!
Name ewp_baseline_plus1: #REF!
Name lambda: 'markov model'!$M$4
Name moddata: 'markov model'!$M$7:$M$3656
Name mu: #REF!
Name mu_err: #REF!
Name obs: 'Calc transition matrix'!#REF!
Name obsdata: 'Calc transition matrix'!$E$2:$E$245
Name pdd: 'markov model'!$E$10
Name pdw: 'markov model'!$D$10
Name pwd: 'markov model'!$E$9
Name pww: 'markov model'!$D$9
Name rainout: 'markov model'!$B$7:$B$3656
Name sd_err: #REF!

Sheet READ ME
A2: Rainfall model - for Newcastle
A4: This spreadsheet provides rainfall series for input to rain water harvesting analysis or flood risk analysis.
A5: The Markov model approach is to be used for wet and dry day sequences, with wet day amounts generated from an exponential distribution.
A6: This is a stochastic model so the outputs will change when re-calculated. To force a re-calculation, press F9
A7: The observed data set which this is based on (Col A on Calc Transition matrix tab) is from 4 rain gauge records from north of Newcastle (Wansbeck catchment), but can be taken as representative of Newcastle.
A8: If adjustment is required, the mean annual rainfall could be changed.
A10: Objectives
A11: First : need to set up the model to reproduce the observed rainfall behaviour.
A12: Second, we will modify the stats to change the daily mean rainfall (to represent cliamte change) by plus and minus 20%.
A14: Statistics to match
A15: 10 years of daily data for area-weighted average for the catchment are given | M15: Daily observed stats to match
A16: Assume that all months are the same - i.e. no seasonal variation in rainfall. | M16: pdry | N16: pww | O16: pdd
M17: 0.43 | N17: 0.72 | O17: 0.62
A18: The model is in two parts : (a) occurrence (wet or dry) and (b) Amounts on wet days | M18: 3.9 | N18: Mean wet day (mm)
A19: (a) Occurrence model (Markov) | M19: 817 | N19: Annual rainfall (mm)
A20: The transition probabilities pww and pdd of the target rainfall regime are given below.
A21: You should use these to calculate the whole transition matrix and use in the Markov model which has already been coded for you.
A22: Check the model performance by comparing the transitions and the pdry (probability of dry day) with the observed
A24: (b) Amount model (Exponential)
A25: The mean rainfall is given: you should use an exponential distribution to model the amount of rainfall.
A26: You can do this by selecting an appropriate lambda value
A28: Future statistics
A30: You will learn how to estimate future climate change in later modules.
A31: Here, we suggets you carry out a sensitivity analysis:
A32: Keeping the transition matrix the same, try increasing (and decreasing) the mean wet day amount by a factor of 1.2

Sheet markov model
A1: Markov model | O1: Observed stats to match | T1: Mean daily rainfall | V1: Annual rainfall | Y1: Mean daily rainfall | Z1: 25 year (1.07) | AA1: Annual rainfall | AD1: Mean daily rainfall | AE1: 50 year (1.14) | AF1: Annual rainfall | AI1: Mean daily rainfall | AJ1: 50 year (1.21) | AK1: Annual rainfall
B2: Occurrence model | E2: Statistics | L2: Amounts model | O2: pdry | P2: pww | Q2: pdd | S2: =S1+1 -> 1 | T2: 2.3510917 | V2: 184.38659 | Y2: 2.6269195 | AA2: 212.31998 | AD2: 2.7517961 | AF2: 227.36376 | AI2: 2.9826524 | AK2: 231.73119
A3: IF(Xt>0,IF(R<pww,1,0),IF(R<pdw,1,0)) | L3: Exponential | P3: 0.77 | Q3: 0.54 | S3: =S2+1 -> 2 | T3: 2.3517268 | V3: 181.30239 | Y3: 2.5820687 | AA3: 209.72722 | AD3: 2.594813 | AF3: 196.23896 | AI3: 2.7156553 | AK3: 213.15879
A4: 5842 days | B4: 1 | C4: w wet | D4: From observed data | G4: From model output | J4: From model output | L4: lambda | M4: =1/M5 -> 0.34482759 | N4: 1/mm | O4: 733.5 | P4: Annual rainfall (mm) | S4: =S3+1 -> 3 | T4: 2.3141116 | V4: 181.3322 | Y4: 2.4938953 | AA4: 183.62162 | AD4: 2.792021 | AF4: 225.10615 | AI4: 2.7538075 | AK4: 215.78647
B5: 0 | C5: d dry | D5: Transition matrix | G5: Stats of model output | J5: pww | K5: pdw | L5: 1/lambda | M5: 2.9 | S5: =S4+1 -> 4 | T5: 2.3934299 | V5: 194.24565 | Y5: 2.5642584 | AA5: 201.44612 | AD5: 2.6977188 | AF5: 214.08772 | AI5: 2.9697516 | AK5: 234.29075
A6: Day | B6: State | C6: Random No: R 0:1 | D6: Pww | E6: Pwd | F6: Sum=1 | G6: pwet | H6: =COUNTIF(rainout,">0")/COUNT(rainout) -> 0.58536585 | J6: =SUM(J7:J3656)/SUM(rainout) -> 0.74113475 | K6: =SUM(K7:K3656)/(3650-SUM(rainout)) -> 0.20103093 | L6: Day | M6: Amount | S6: =S5+1 -> 5 | T6: 2.3200061 | V6: 176.69272 | Y6: 2.6492293 | AA6: 201.41347 | AD6: 2.7728874 | AF6: 214.69487 | AI6: 2.9496141 | AK6: 239.58091
A7: 1 | B7: 1 | C7: =RAND() -> 0.94495199 | D7: Pdw | E7: Pdd | F7: Sum=1 | G7: pdry | H7: =COUNTIF(rainout,"=0")/COUNT(rainout) -> 0.41463415 | J7: =IF(AND(B7,B8),1,0) -> 0 | K7: =IF(AND(NOT(B7),NOT(B8)),1,0) -> 0 | L7: 1 | M7: =IF(B7>0,-LN(1-(RAND()))/lambda,0) -> 1.351305 | P7: raindays | S7: =S6+1 -> 6 | T7: 2.4359501 | V7: 186.01001 | Y7: 2.6749189 | AA7: 212.45658 | AD7: 2.9013323 | AF7: 226.37981 | AI7: 2.81291 | AK7: 219.29312
A8: 2 | B8: =IF(B7>0,IF(C8<pww,1,0),IF(C8<pdw,1,0)) -> 0 | C8: =RAND() -> 0.92819575 | G8: Transition matrix | J8: =IF(AND(B8,B9),1,0) -> 0 | K8: =IF(AND(NOT(B8),NOT(B9)),1,0) -> 0 | L8: 2 | M8: =IF(B8>0,-LN(1-(RAND()))/lambda,0) -> 0 | P8: mean daily rainfall (mm) | S8: =S7+1 -> 7 | T8: 2.2982148 | V8: 179.01459 | Y8: 2.4022063 | AA8: 196.71863 | AD8: 2.5563507 | AF8: 201.67657 | AI8: 2.8802461 | AK8: 216.29019
A9: 3 | B9: =IF(B8>0,IF(C9<pww,1,0),IF(C9<pdw,1,0)) -> 1 | C9: =RAND() -> 0.011832367 | D9: 0.75 | E9: =1-pww -> 0.25 | F9: Sum=1 | G9: =J6 -> 0.74113475 | H9: =1-G9 -> 0.25886525 | J9: =IF(AND(B9,B10),1,0) -> 1 | K9: =IF(AND(NOT(B9),NOT(B10)),1,0) -> 0 | L9: 3 | M9: =IF(B9>0,-LN(1-(RAND()))/lambda,0) -> 5.8863743 | O9: Mean daily rainfall | Q9: Annual rainfall | S9: =S8+1 -> 8 | T9: 2.4901401 | V9: 193.96421 | Y9: 2.682215 | AA9: 214.28712 | AD9: 2.7323181 | AF9: 209.00489 | AI9: 2.9068953 | AK9: 232.43094
A10: 4 | B10: =IF(B9>0,IF(C10<pww,1,0),IF(C10<pdw,1,0)) -> 1 | C10: =RAND() -> 0.20154542 | D10: =1-pdd -> 0.39 | E10: 0.61 | F10: Sum=1 | G10: =1-H10 -> 0.79896907 | H10: =K6 -> 0.20103093 | J10: =IF(AND(B10,B11),1,0) -> 0 | K10: =IF(AND(NOT(B10),NOT(B11)),1,0) -> 0 | L10: 4 | M10: =IF(B10>0,-LN(1-(RAND()))/lambda,0) -> 4.0814234 | O10: =SUM(M7:M5849)/1926/H6 -> 2.7794985 | Q10: =SUM(M7:M5849)/15 -> 208.90982 | R10: mm | S10: =S9+1 -> 9 | T10: 2.4589185 | V10: 195.62834 | Y10: 2.561037 | AA10: 201.36369 | AD10: 2.7364514 | AF10: 219.34951 | AI10: 2.8315822 | AK10: 215.84327
A11: 5 | B11: =IF(B10>0,IF(C11<pww,1,0),IF(C11<pdw,1,0)) -> 0 | C11: =RAND() -> 0.80616645 | J11: =IF(AND(B11,B12),1,0) -> 0 | K11: =IF(AND(NOT(B11),NOT(B12)),1,0) -> 1 | L11: 5 | M11: =IF(B11>0,-LN(1-(RAND()))/lambda,0) -> 0 | Q11: Check this!! | S11: =S10+1 -> 10 | T11: 2.2701556 | V11: 174.86254 | Y11: 2.6117747 | AA11: 206.39715 | AD11: 2.8005802 | AF11: 220.01137 | AI11: 2.9872474 | AK11: 227.31108
A12: 6 | B12: =IF(B11>0,IF(C12<pww,1,0),IF(C12<pdw,1,0)) -> 0 | C12: =RAND() -> 0.68531882 | J12: =IF(AND(B12,B13),1,0) -> 0 | K12: =IF(AND(NOT(B12),NOT(B13)),1,0) -> 0 | L12: 6 | M12: =IF(B12>0,-LN(1-(RAND()))/lambda,0) -> 0 | S12: =S11+1 -> 11 | T12: 2.3951148 | V12: 184.9665 | Y12: 2.6350566 | AA12: 203.67196 | AD12: 2.7853288 | AF12: 216.95731 | AI12: 2.8675937 | AK12: 221.26335
A13: 7 | B13: =IF(B12>0,IF(C13<pww,1,0),IF(C13<pdw,1,0)) -> 1 | C13: =RAND() -> 0.24024083 | J13: =IF(AND(B13,B14),1,0) -> 0 | K13: =IF(AND(NOT(B13),NOT(B14)),1,0) -> 0 | L13: 7 | M13: =IF(B13>0,-LN(1-(RAND()))/lambda,0) -> 1.3417132 | O13: Max | P13: Obs | Q13: =MAX(obsdata) -> 26.666667 | R13: mm | S13: =S12+1 -> 12 | T13: 2.420793 | V13: 191.94991 | Y13: 2.5063046 | AA13: 197.89531 | AD13: 2.7605669 | AF13: 222.01834 | AI13: 2.9445733 | AK13: 238.97527
A14: 8 | B14: =IF(B13>0,IF(C14<pww,1,0),IF(C14<pdw,1,0)) -> 0 | C14: =RAND() -> 0.97589476 | J14: =IF(AND(B14,B15),1,0) -> 0 | K14: =IF(AND(NOT(B14),NOT(B15)),1,0) -> 0 | L14: 8 | M14: =IF(B14>0,-LN(1-(RAND()))/lambda,0) -> 0 | P14: Model | Q14: =MAX(M7:M5849) -> 19.121177 | R14: mm | S14: =S13+1 -> 13 | T14: 2.4400813 | V14: 181.12267 | Y14: 2.6138503 | AA14: 203.77452 | AD14: 2.7439598 | AF14: 213.36929 | AI14: 2.8495894 | AK14: 226.13999
A15: 9 | B15: =IF(B14>0,IF(C15<pww,1,0),IF(C15<pdw,1,0)) -> 1 | C15: =RAND() -> 0.28625829 | J15: =IF(AND(B15,B16),1,0) -> 1 | K15: =IF(AND(NOT(B15),NOT(B16)),1,0) -> 0 | L15: 9 | M15: =IF(B15>0,-LN(1-(RAND()))/lambda,0) -> 12.14688 | S15: =S14+1 -> 14 | T15: 2.4869447 | V15: 190.89824 | Y15: 2.6327795 | AA15: 214.37247 | AD15: 2.7676127 | AF15: 216.13059 | AI15: 3.0403954 | AK15: 233.98895
A16: 10 | B16: =IF(B15>0,IF(C16<pww,1,0),IF(C16<pdw,1,0)) -> 1 | C16: =RAND() -> 0.47474915 | J16: =IF(AND(B16,B17),1,0) -> 1 | K16: =IF(AND(NOT(B16),NOT(B17)),1,0) -> 0 | L16: 10 | M16: =IF(B16>0,-LN(1-(RAND()))/lambda,0) -> 0.70119843 | S16: =S15+1 -> 15 | T16: 2.3351926 | V16: 190.60843 | Y16: 2.6278269 | AA16: 210.99255 | AD16: 2.7971269 | AF16: 218.99457 | AI16: 2.9307455 | AK16: 232.77572
A17: 11 | B17: =IF(B16>0,IF(C17<pww,1,0),IF(C17<pdw,1,0)) -> 1 | C17: =RAND() -> 0.1118509 | J17: =IF(AND(B17,B18),1,0) -> 1 | K17: =IF(AND(NOT(B17),NOT(B18)),1,0) -> 0 | L17: 11 | M17: =IF(B17>0,-LN(1-(RAND()))/lambda,0) -> 0.26565698 | S17: =S16+1 -> 16 | T17: 2.3897582 | V17: 189.96681 | Y17: 2.504943 | AA17: 196.11871 | AD17: 2.6610258 | AF17: 199.82799 | AI17: 2.9454675 | AK17: 229.03845
A18: 12 | B18: =IF(B17>0,IF(C18<pww,1,0),IF(C18<pdw,1,0)) -> 1 | C18: =RAND() -> 0.73140638 | J18: =IF(AND(B18,B19),1,0) -> 1 | K18: =IF(AND(NOT(B18),NOT(B19)),1,0) -> 0 | L18: 12 | M18: =IF(B18>0,-LN(1-(RAND()))/lambda,0) -> 6.1357074 | S18: =S17+1 -> 17 | T18: 2.3774483 | V18: 181.70121 | Y18: 2.4818077 | AA18: 193.97665 | AD18: 2.715844 | AF18: 210.09724 | AI18: 2.9510015 | AK18: 234.38456
A19: 13 | B19: =IF(B18>0,IF(C19<pww,1,0),IF(C19<pdw,1,0)) -> 1 | C19: =RAND() -> 0.39219247 | J19: =IF(AND(B19,B20),1,0) -> 1 | K19: =IF(AND(NOT(B19),NOT(B20)),1,0) -> 0 | L19: 13 | M19: =IF(B19>0,-LN(1-(RAND()))/lambda,0) -> 0.9934614 | S19: =S18+1 -> 18 | T19: 2.4512581 | V19: 193.5489 | Y19: 2.6593101 | AA19: 196.86402 | AD19: 2.6106292 | AF19: 214.13445 | AI19: 2.9486423 | AK19: 233.21481
A20: 14 | B20: =IF(B19>0,IF(C20<pww,1,0),IF(C20<pdw,1,0)) -> 1 | C20: =RAND() -> 0.74121853 | J20: =IF(AND(B20,B21),1,0) -> 0 | K20: =IF(AND(NOT(B20),NOT(B21)),1,0) -> 0 | L20: 14 | M20: =IF(B20>0,-LN(1-(RAND()))/lambda,0) -> 0.34210294 | S20: =S19+1 -> 19 | T20: 2.3150406 | V20: 185.56991 | Y20: 2.5676519 | AA20: 197.26442 | AD20: 2.7694305 | AF20: 213.50456 | AI20: 3.0790225 | AK20: 238.19267
A21: 15 | B21: =IF(B20>0,IF(C21<pww,1,0),IF(C21<pdw,1,0)) -> 0 | C21: =RAND() -> 0.75405345 | J21: =IF(AND(B21,B22),1,0) -> 0 | K21: =IF(AND(NOT(B21),NOT(B22)),1,0) -> 1 | L21: 15 | M21: =IF(B21>0,-LN(1-(RAND()))/lambda,0) -> 0 | S21: =S20+1 -> 20 | T21: 2.3572535 | V21: 181.57139 | Y21: 2.6674061 | AA21: 205.63915 | AD21: 2.7824964 | AF21: 217.2929 | AI21: 2.7798126 | AK21: 213.56405
A22: 16 | B22: =IF(B21>0,IF(C22<pww,1,0),IF(C22<pdw,1,0)) -> 0 | C22: =RAND() -> 0.48710889 | J22: =IF(AND(B22,B23),1,0) -> 0 | K22: =IF(AND(NOT(B22),NOT(B23)),1,0) -> 1 | L22: 16 | M22: =IF(B22>0,-LN(1-(RAND()))/lambda,0) -> 0 | S22: =S21+1 -> 21 | T22: 2.3641843 | V22: 169.50281 | Y22: 2.5683218 | AA22: 202.79213 | AD22: 2.7625526 | AF22: 225.49138 | AI22: 3.0622466 | AK22: 246.48495
A23: 17 | B23: =IF(B22>0,IF(C23<pww,1,0),IF(C23<pdw,1,0)) -> 0 | C23: =RAND() -> 0.5463459 | J23: =IF(AND(B23,B24),1,0) -> 0 | K23: =IF(AND(NOT(B23),NOT(B24)),1,0) -> 1 | L23: 17 | M23: =IF(B23>0,-LN(1-(RAND()))/lambda,0) -> 0 | S23: =S22+1 -> 22 | T23: 2.4212828 | V23: 189.24605 | Y23: 2.5444631 | AA23: 197.51741 | AD23: 2.8454238 | AF23: 221.44868 | AI23: 2.9082569 | AK23: 230.60198
A24: 18 | B24: =IF(B23>0,IF(C24<pww,1,0),IF(C24<pdw,1,0)) -> 0 | C24: =RAND() -> 0.97952817 | J24: =IF(AND(B24,B25),1,0) -> 0 | K24: =IF(AND(NOT(B24),NOT(B25)),1,0) -> 1 | L24: 18 | M24: =IF(B24>0,-LN(1-(RAND()))/lambda,0) -> 0 | S24: =S23+1 -> 23 | T24: 2.387599 | V24: 191.54516 | Y24: 2.6172066 | AA24: 199.32765 | AD24: 2.653143 | AF24: 207.19133 | AI24: 2.8856148 | AK24: 231.30621
A25: 19 | B25: =IF(B24>0,IF(C25<pww,1,0),IF(C25<pdw,1,0)) -> 0 | C25: =RAND() -> 0.68297375 | J25: =IF(AND(B25,B26),1,0) -> 0 | K25: =IF(AND(NOT(B25),NOT(B26)),1,0) -> 1 | L25: 19 | M25: =IF(B25>0,-LN(1-(RAND()))/lambda,0) -> 0 | S25: =S24+1 -> 24 | T25: 2.5084151 | V25: 197.72768 | Y25: 2.6924413 | AA25: 218.33338 | AD25: 2.6803185 | AF25: 208.42057 | AI25: 2.9042433 | AK25: 229.31615
A26: 20 | B26: =IF(B25>0,IF(C26<pww,1,0),IF(C26<pdw,1,0)) -> 0 | C26: =RAND() -> 0.99076693 | J26: =IF(AND(B26,B27),1,0) -> 0 | K26: =IF(AND(NOT(B26),NOT(B27)),1,0) -> 1 | L26: 20 | M26: =IF(B26>0,-LN(1-(RAND()))/lambda,0) -> 0 | S26: =S25+1 -> 25 | T26: 2.445674 | V26: 193.92278 | Y26: 2.4644214 | AA26: 184.24306 | AD26: 2.6923137 | AF26: 216.1703 | AI26: 2.9494256 | AK26: 233.86634
A27: 21 | B27: =IF(B26>0,IF(C27<pww,1,0),IF(C27<pdw,1,0)) -> 0 | C27: =RAND() -> 0.77827386 | J27: =IF(AND(B27,B28),1,0) -> 0 | K27: =IF(AND(NOT(B27),NOT(B28)),1,0) -> 1 | L27: 21 | M27: =IF(B27>0,-LN(1-(RAND()))/lambda,0) -> 0 | O27: Inverse cumulative distribution function | S27: =S26+1 -> 26 | T27: 2.2635097 | V27: 172.54076 | Y27: 2.5111726 | AA27: 191.75403 | AD27: 2.7750716 | AF27: 209.87145 | AI27: 2.7896359 | AK27: 213.7611
A28: 22 | B28: =IF(B27>0,IF(C28<pww,1,0),IF(C28<pdw,1,0)) -> 0 | C28: =RAND() -> 0.77769241 | J28: =IF(AND(B28,B29),1,0) -> 0 | K28: =IF(AND(NOT(B28),NOT(B29)),1,0) -> 0 | L28: 22 | M28: =IF(B28>0,-LN(1-(RAND()))/lambda,0) -> 0 | S28: =S27+1 -> 27 | T28: 2.2667227 | V28: 171.72841 | Y28: 2.6675063 | AA28: 202.26979 | AD28: 2.6967265 | AF28: 215.80585 | AI28: 3.0186605 | AK28: 237.14359
A29: 23 | B29: =IF(B28>0,IF(C29<pww,1,0),IF(C29<pdw,1,0)) -> 1 | C29: =RAND() -> 0.016176047 | J29: =IF(AND(B29,B30),1,0) -> 1 | K29: =IF(AND(NOT(B29),NOT(B30)),1,0) -> 0 | L29: 23 | M29: =IF(B29>0,-LN(1-(RAND()))/lambda,0) -> 2.0649278 | S29: =S28+1 -> 28 | T29: 2.3769381 | V29: 182.13735 | Y29: 2.5866828 | AA29: 203.0354 | AD29: 2.6395965 | AF29: 215.63106 | AI29: 2.9550281 | AK29: 231.16018
A30: 24 | B30: =IF(B29>0,IF(C30<pww,1,0),IF(C30<pdw,1,0)) -> 1 | C30: =RAND() -> 0.40449317 | J30: =IF(AND(B30,B31),1,0) -> 0 | K30: =IF(AND(NOT(B30),NOT(B31)),1,0) -> 0 | L30: 24 | M30: =IF(B30>0,-LN(1-(RAND()))/lambda,0) -> 0.18383397 | S30: =S29+1 -> 29 | T30: 2.3977701 | V30: 182.61526 | Y30: 2.5778224 | AA30: 208.35173 | AD30: 2.7210046 | AF30: 213.75997 | AI30: 2.9814283 | AK30: 222.29913
A31: 25 | B31: =IF(B30>0,IF(C31<pww,1,0),IF(C31<pdw,1,0)) -> 0 | C31: =RAND() -> 0.93711522 | J31: =IF(AND(B31,B32),1,0) -> 0 | K31: =IF(AND(NOT(B31),NOT(B32)),1,0) -> 0 | L31: 25 | M31: =IF(B31>0,-LN(1-(RAND()))/lambda,0) -> 0 | S31: =S30+1 -> 30 | T31: 2.4549647 | V31: 186.64407 | Y31: 2.656258 | AA31: 203.89475 | AD31: 2.6661846 | AF31: 205.18967 | AI31: 2.8622683 | AK31: 211.50722
A32: 26 | B32: =IF(B31>0,IF(C32<pww,1,0),IF(C32<pdw,1,0)) -> 1 | C32: =RAND() -> 0.012453992 | J32: =IF(AND(B32,B33),1,0) -> 1 | K32: =IF(AND(NOT(B32),NOT(B33)),1,0) -> 0 | L32: 26 | M32: =IF(B32>0,-LN(1-(RAND()))/lambda,0) -> 2.0419699 | S32: =S31+1 -> 31 | T32: 2.3747378 | V32: 186.08282 | Y32: 2.5108325 | AA32: 193.56837 | AD32: 2.701038 | AF32: 207.33207 | AI32: 2.7939379 | AK32: 231.96267
A33: 27 | B33: =IF(B32>0,IF(C33<pww,1,0),IF(C33<pdw,1,0)) -> 1 | C33: =RAND() -> 0.32702118 | J33: =IF(AND(B33,B34),1,0) -> 1 | K33: =IF(AND(NOT(B33),NOT(B34)),1,0) -> 0 | L33: 27 | M33: =IF(B33>0,-LN(1-(RAND()))/lambda,0) -> 0.033756742 | S33: =S32+1 -> 32 | T33: 2.4443996 | V33: 187.79534 | Y33: 2.6324864 | AA33: 203.99953 | AD33: 2.8280719 | AF33: 233.8544 | AI33: 2.95915 | AK33: 235.62328
A34: 28 | B34: =IF(B33>0,IF(C34<pww,1,0),IF(C34<pdw,1,0)) -> 1 | C34: =RAND() -> 0.74940595 | J34: =IF(AND(B34,B35),1,0) -> 0 | K34: =IF(AND(NOT(B34),NOT(B35)),1,0) -> 0 | L34: 28 | M34: =IF(B34>0,-LN(1-(RAND()))/lambda,0) -> 1.5448075 | S34: =S33+1 -> 33 | T34: 2.463736 | V34: 188.95257 | Y34: 2.5418573 | AA34: 196.63766 | AD34: 2.781637 | AF34: 214.0749 | AI34: 2.8807963 | AK34: 232.4556
A35: 29 | B35: =IF(B34>0,IF(C35<pww,1,0),IF(C35<pdw,1,0)) -> 0 | C35: =RAND() -> 0.97725695 | J35: =IF(AND(B35,B36),1,0) -> 0 | K35: =IF(AND(NOT(B35),NOT(B36)),1,0) -> 0 | L35: 29 | M35: =IF(B35>0,-LN(1-(RAND()))/lambda,0) -> 0 | S35: =S34+1 -> 34 | T35: 2.4390908 | V35: 190.15036 | Y35: 2.6372766 | AA35: 206.65519 | AD35: 2.7845406 | AF35: 214.11282 | AI35: 3.014945 | AK35: 235.44546
A36: 30 | B36: =IF(B35>0,IF(C36<pww,1,0),IF(C36<pdw,1,0)) -> 1 | C36: =RAND() -> 0.15495731 | J36: =IF(AND(B36,B37),1,0) -> 0 | K36: =IF(AND(NOT(B36),NOT(B37)),1,0) -> 0 | L36: 30 | M36: =IF(B36>0,-LN(1-(RAND()))/lambda,0) -> 2.2907982 | S36: =S35+1 -> 35 | T36: 2.3455168 | V36: 176.76019 | Y36: 2.5438783 | AA36: 190.35286 | AD36: 2.7389878 | AF36: 213.16518 | AI36: 2.8437002 | AK36: 220.36714
A37: 31 | B37: =IF(B36>0,IF(C37<pww,1,0),IF(C37<pdw,1,0)) -> 0 | C37: =RAND() -> 0.92242045 | J37: =IF(AND(B37,B38),1,0) -> 0 | K37: =IF(AND(NOT(B37),NOT(B38)),1,0) -> 0 | L37: 31 | M37: =IF(B37>0,-LN(1-(RAND()))/lambda,0) -> 0 | S37: =S36+1 -> 36 | T37: 2.4699894 | V37: 193.05294 | Y37: 2.5535686 | AA37: 204.51977 | AD37: 2.7035436 | AF37: 212.5684 | AI37: 2.883089 | AK37: 228.99058
A38: 32 | B38: =IF(B37>0,IF(C38<pww,1,0),IF(C38<pdw,1,0)) -> 1 | C38: =RAND() -> 0.12962293 | J38: =IF(AND(B38,B39),1,0) -> 1 | K38: =IF(AND(NOT(B38),NOT(B39)),1,0) -> 0 | L38: 32 | M38: =IF(B38>0,-LN(1-(RAND()))/lambda,0) -> 8.6606049 | S38: =S37+1 -> 37 | T38: 2.3844915 | V38: 185.0994 | Y38: 2.5594178 | AA38: 197.14344 | AD38: 2.701489 | AF38: 217.087 | AI38: 2.9050659 | AK38: 230.73611
A39: 33 | B39: =IF(B38>0,IF(C39<pww,1,0),IF(C39<pdw,1,0)) -> 1 | C39: =RAND() -> 0.53589465 | J39: =IF(AND(B39,B40),1,0) -> 0 | K39: =IF(AND(NOT(B39),NOT(B40)),1,0) -> 0 | L39: 33 | M39: =IF(B39>0,-LN(1-(RAND()))/lambda,0) -> 1.9508148 | S39: =S38+1 -> 38 | T39: 2.4427991 | V39: 186.37023 | Y39: 2.5833917 | AA39: 204.15417 | AD39: 2.741081 | AF39: 210.77106 | AI39: 2.8440418 | AK39: 228.73181
... A51: 45 | B51: =IF(B50>0,IF(C51<pww,1,0),IF(C51<pdw,1,0)) -> 1 | C51: =RAND() -> 0.14414242 | J51: =IF(AND(B51,B52),1,0) -> 1 | K51: =IF(AND(NOT(B51),NOT(B52)),1,0) -> 0 | L51: 45 | M51: =IF(B51>0,-LN(1-(RAND()))/lambda,0) -> 0.6808114 | S51: =S50+1 -> 50 | T51: 2.3492241 | V51: 184.24012 | Y51: 2.6792592 | AA51: 204.41065 | AD51: 2.6430425 | AF51: 209.22034 | AI51: 2.9500154 | AK51: 223.29856
...

Sheet Output analysis
B1: Seasonal | F1: Annual | N1: Model monthly analysis | W1: Row Labels | X1: Sum of Obs rainfall (mm) | Y1: Months | Z1: SD
B2: Month | C2: OBS | D2: MOD | F2: year | G2: Obs | H2: model | N2: Monthly | O2: Cumulative | P2: Total monthly | Q2: Mean monthly | R2: SD monthly | W2: 1 | X2: 101.52526 | Y2: 101.52526 | Z2: =_xlfn.STDEV.S(Y2:Y121) -> 36.578202
B3: 1 | C3: 77.2809 | D3: =Q3 -> 31.073863 | F3: 2003 | G3: 587.88028 | H3: =SUM('markov model'!M7:M371) -> 575.51783 | M3: 1 | O3: 1 | P3: =SUMIFS('markov model'!M$7:M$3656, 'markov model'!L$7:L$3656,">="&O3,'markov model'!L$7:L$3656,"<"&O4) -> 41.405917 | Q3: =AVERAGE(P3,P15,P27,P39,P51,P63,P75,P87,P99,P111) -> 31.073863 | R3: =_xlfn.STDEV.S(P3,P15,P27,P39,P51,P63,P75,P87,P99,P111) -> 29.518477 | W3: 2 | X3: 22.080277 | Y3: 22.080277
B4: 2 | C4: 52.23737 | D4: =Q4 -> 26.015598 | F4: 2004 | G4: 898.94325 | H4: =SUM('markov model'!M372:M737) -> 551.9919 | M4: 2 | N4: 31 | O4: =SUM(N$4:N4) -> 31 | P4: =SUMIFS('markov model'!M$7:M$3656, 'markov model'!L$7:L$3656,">="&O4,'markov model'!L$7:L$3656,"<"&O5) -> 27.967549 | Q4: =AVERAGE(P4,P16,P28,P40,P52,P64,P76,P88,P100,P112) -> 26.015598 | R4: =_xlfn.STDEV.S(P4,P16,P28,P40,P52,P64,P76,P88,P100,P112) -> 25.294784 | W4: 3 | X4: 23.63045 | Y4: 23.63045
B5: 3 | C5: 55.498962 | D5: =Q5 -> 34.156896 | F5: 2005 | G5: 819.81038 | H5: =SUM('markov model'!M738:M1102) -> 605.30613 | M5: 3 | N5: 28 | O5: =SUM(N$4:N5) -> 59 | P5: =SUMIFS('markov model'!M$7:M$3656, 'markov model'!L$7:L$3656,">="&O5,'markov model'!L$7:L$3656,"<"&O6) -> 56.988069 | Q5: =AVERAGE(P5,P17,P29,P41,P53,P65,P77,P89,P101,P113) -> 34.156896 | R5: =_xlfn.STDEV.S(P5,P17,P29,P41,P53,P65,P77,P89,P101,P113) -> 31.237683 | W5: 4 | X5: 31.551557 | Y5: 31.551557
B6: 4 | C6: 54.071142 | D6: =Q6 -> 26.134974 | F6: 2006 | G6: 700.90796 | H6: =SUM('markov model'!M1103:M1467) -> 542.10627 | M6: 4 | N6: 31 | O6: =SUM(N$4:N6) -> 90 | P6: =SUMIFS('markov model'!M$7:M$3656, 'markov model'!L$7:L$3656,">="&O6,'markov model'!L$7:L$3656,"<"&O7) -> 52.718925 | Q6: =AVERAGE(P6,P18,P30,P42,P54,P66,P78,P90,P102,P114) -> 26.134974 | R6: =_xlfn.STDEV.S(P6,P18,P30,P42,P54,P66,P78,P90,P102,P114) -> 26.029064 | W6: 5 | X6: 79.628374 | Y6: 79.628374
B7: 5 | C7: 49.716401 | D7: =Q7 -> 22.696141 | F7: 2007 | G7: 697.16471 | H7: =SUM('markov model'!M1468:M1832) -> 642.68632 | M7: 5 | N7: 30 | O7: =SUM(N$4:N7) -> 120 | P7: =SUMIFS('markov model'!M$7:M$3656, 'markov model'!L$7:L$3656,">="&O7,'markov model'!L$7:L$3656,"<"&O8) -> 64.862083 | Q7: =AVERAGE(P7,P19,P31,P43,P55,P67,P79,P91,P103,P115) -> 22.696141 | R7: =_xlfn.STDEV.S(P7,P19,P31,P43,P55,P67,P79,P91,P103,P115) -> 26.162214 | W7: 6 | X7: 69.797232 | Y7: 69.797232
B8: 6 | C8: 78.112249 | D8: =Q8 -> 23.955923 | F8: 2008 | G8: 1007.3578 | H8: =SUM('markov model'!M1833:M2197) -> 216.03885 | M8: 6 | N8: 31 | O8: =SUM(N$4:N8) -> 151 | P8: =SUMIFS('markov model'!M$7:M$3656, 'markov model'!L$7:L$3656,">="&O8,'markov model'!L$7:L$3656,"<"&O9) -> 41.513047 | Q8: =AVERAGE(P8,P20,P32,P44,P56,P68,P80,P92,P104,P116) -> 23.955923 | R8: =_xlfn.STDEV.S(P8,P20,P32,P44,P56,P68,P80,P92,P104,P116) -> 26.541982 | W8: 7 | X8: 37.83737 | Y8: 37.83737
B9: 7 | C9: 77.903806 | D9: =Q9 -> 30.567699 | F9: 2009 | G9: 818.31834 | H9: =SUM('markov model'!M2198:M2562) -> 0 | M9: 7 | N9: 30 | O9: =SUM(N$4:N9) -> 181 | P9: =SUMIFS('markov model'!M$7:M$3656, 'markov model'!L$7:L$3656,">="&O9,'markov model'!L$7:L$3656,"<"&O10) -> 56.053844 | Q9: =AVERAGE(P9,P21,P33,P45,P57,P69,P81,P93,P105,P117) -> 30.567699 | R9: =_xlfn.STDEV.S(P9,P21,P33,P45,P57,P69,P81,P93,P105,P117) -> 38.368367 | W9: 8 | X9: 10.770242 | Y9: 10.770242
B10: 8 | C10: 82.782837 | D10: =Q10 -> 19.850218 | F10: 2010 | G10: 842.67889 | H10: =SUM('markov model'!M2562:M2927) -> 0 | M10: 8 | N10: 31 | O10: =SUM(N$4:N10) -> 212 | P10: =SUMIFS('markov model'!M$7:M$3656, 'markov model'!L$7:L$3656,">="&O10,'markov model'!L$7:L$3656,"<"&O11) -> 47.517646 | Q10: =AVERAGE(P10,P22,P34,P46,P58,P70,P82,P94,P106,P118) -> 19.850218 | R10: =_xlfn.STDEV.S(P10,P22,P34,P46,P58,P70,P82,P94,P106,P118) -> 22.458222 | W10: 9 | X10: 47.817993 | Y10: 47.817993
B11: 9 | C11: 68.414187 | D11: =Q11 -> 29.465949 | F11: 2011 | G11: 763.56125 | H11: =SUM('markov model'!M2928:M3292) -> 0 | M11: 9 | N11: 31 | O11: =SUM(N$4:N11) -> 243 | P11: =SUMIFS('markov model'!M$7:M$3656, 'markov model'!L$7:L$3656,">="&O11,'markov model'!L$7:L$3656,"<"&O12) -> 45.557703 | Q11: =AVERAGE(P11,P23,P35,P47,P59,P71,P83,P95,P107,P119) -> 29.465949 | R11: =_xlfn.STDEV.S(P11,P23,P35,P47,P59,P71,P83,P95,P107,P119) -> 34.442942 | W11: 10 | X11: 39.852595 | Y11: 39.852595
B12: 10 | C12: 71.734394 | D12: =Q12 -> 24.94208 | F12: 2012 | G12: 1040.6533 | H12: =SUM('markov model'!M3293:M3657) -> 0 | M12: 10 | N12: 30 | O12: =SUM(N$4:N12) -> 273 | P12: =SUMIFS('markov model'!M$7:M$3656, 'markov model'!L$7:L$3656,">="&O12,'markov model'!L$7:L$3656,"<"&O13) -> 36.383673 | Q12: =AVERAGE(P12,P24,P36,P48,P60,P72,P84,P96,P108,P120) -> 24.94208 | R12: =_xlfn.STDEV.S(P12,P24,P36,P48,P60,P72,P84,P96,P108,P120) -> 28.186008 | W12: 11 | X12: 42.5391 | Y12: 42.5391
B13: 11 | C13: 78.420208 | D13: =Q13 -> 24.975669 | F13: SD | G13: =_xlfn.STDEV.S(G3:G12) -> 140.16844 | H13: =_xlfn.STDEV.S(H3:H12) -> 293.24516 | M13: 11 | N13: 31 | O13: =SUM(N$4:N13) -> 304 | P13: =SUMIFS('markov model'!M$7:M$3656, 'markov model'!L$7:L$3656,">="&O13,'markov model'!L$7:L$3656,"<"&O14) -> 53.244002 | Q13: =AVERAGE(P13,P25,P37,P49,P61,P73,P85,P97,P109,P121) -> 24.975669 | R13: =_xlfn.STDEV.S(P13,P25,P37,P49,P61,P73,P85,P97,P109,P121) -> 26.564977 | W13: 12 | X13: 80.849827 | Y13: 80.849827
B14: 12 | C14: 71.555156 | D14: =Q14 -> 19.529719 | I14: Max + Min | J14: Obs | K14: =MIN(G3:G12) -> 587.88028 | L14: =MAX(G3:G12) -> 1040.6533 | M14: 12 | N14: 30 | O14: =SUM(N$4:N14) -> 334 | P14: =SUMIFS('markov model'!M$7:M$3656, 'markov model'!L$7:L$3656,">="&O14,'markov model'!L$7:L$3656,"<"&O15) -> 51.305368 | Q14: =AVERAGE(P14,P26,P38,P50,P62,P74,P86,P98,P110,P122) -> 19.529719 | R14: =_xlfn.STDEV.S(P14,P26,P38,P50,P62,P74,P86,P98,P110,P122) -> 22.1417 | W14: 13 | X14: 115.75779 | Y14: 115.75779
J15: Model | K15: =MIN(H3:H12) -> 0 | L15: =MAX(H3:H12) -> 642.68632 | M15: 1 | N15: 31 | O15: =SUM(N$4:N15) -> 365 | P15: =SUMIFS('markov model'!M$7:M$3656, 'markov model'!L$7:L$3656,">="&O15,'markov model'!L$7:L$3656,"<"&O16) -> 47.339254 | W15: 14 | X15: 52.662976 | Y15: 52.662976
M16: 2 | N16: 31 | O16: =SUM(N$4:N16) -> 396 | P16: =SUMIFS('markov model'!M$7:M$3656, 'markov model'!L$7:L$3656,">="&O16,'markov model'!L$7:L$3656,"<"&O17) -> 43.278866 | W16: 15 | X16: 59.998616 | Y16: 59.998616
M17: 3 | N17: 28 | O17: =SUM(N$4:N17) -> 424 | P17: =SUMIFS('markov model'!M$7:M$3656, 'markov model'!L$7:L$3656,">="&O17,'markov model'!L$7:L$3656,"<"&O18) -> 61.558992 | S17: Histogram | T17: =SUM(T20:T48) -> 244 | U17: =SUM(U20:U48) -> 1927 | V17: count | W17: 16 | X17: 53.184083 | Y17: 53.184083
M18: 4 | N18: 31 | O18: =SUM(N$4:N18) -> 455 | P18: =SUMIFS('markov model'!M$7:M$3656, 'markov model'!L$7:L$3656,">="&O18,'markov model'!L$7:L$3656,"<"&O19) -> 32.892837 | T18: =MAX(obsdata) -> 26.666667 | U18: =MAX(moddata) -> 19.121177 | V18: max (mm) | W18: 17 | X18: 25.549481 | Y18: 25.549481
M19: 5 | N19: 30 | O19: =SUM(N$4:N19) -> 485 | P19: =SUMIFS('markov model'!M$7:M$3656, 'markov model'!L$7:L$3656,">="&O19,'markov model'!L$7:L$3656,"<"&O20) -> 56.382082 | S19: Amount(mm) | T19: Obs | U19: Model | W19: 18 | X19: 112.43737 | Y19: 112.43737
M20: 6 | N20: 31 | O20: =SUM(N$4:N20) -> 516 | P20: =SUMIFS('markov model'!M$7:M$3656, 'markov model'!L$7:L$3656,">="&O20,'markov model'!L$7:L$3656,"<"&O21) -> 45.167866 | S20: 0 | T20: =COUNTIF(obsdata,"=0") -> 88 | U20: =COUNTIF(moddata,"=0") -> 799 | W20: 19 | X20: 72.303114 | Y20: 72.303114
M21: 7 | N21: 30 | O21: =SUM(N$4:N21) -> 546 | P21: =SUMIFS('markov model'!M$7:M$3656, 'markov model'!L$7:L$3656,">="&O21,'markov model'!L$7:L$3656,"<"&O22) -> 42.15993 | S21: 1 | T21: =COUNTIF(obsdata,"<"&S21)-SUM(T$20:T20) -> 76 | U21: =COUNTIF(moddata,"<"&S21)-SUM(U$20:U20) -> 337 | W21: 20 | X21: 179.82215 | Y21: 179.82215
M22: 8 | N22: 31 | O22: =SUM(N$4:N22) -> 577 | P22: =SUMIFS('markov model'!M$7:M$3656, 'markov model'!L$7:L$3656,">="&O22,'markov model'!L$7:L$3656,"<"&O23) -> 33.665646 | S22: 2 | T22: =COUNTIF(obsdata,"<"&S22)-SUM(T$20:T21) -> 24 | U22: =COUNTIF(moddata,"<"&S22)-SUM(U$20:U21) -> 243 | W22: 21 | X22: 27.607612 | Y22: 27.607612
M23: 9 | N23: 31 | O23: =SUM(N$4:N23) -> 608 | P23: =SUMIFS('markov model'!M$7:M$3656, 'markov model'!L$7:L$3656,">="&O23,'markov model'!L$7:L$3656,"<"&O24) -> 57.897788 | S23: 3 | T23: =COUNTIF(obsdata,"<"&S23)-SUM(T$20:T22) -> 13 | U23: =COUNTIF(moddata,"<"&S23)-SUM(U$20:U22) -> 148 | W23: 22 | X23: 125.24498 | Y23: 125.24498
M24: 10 | N24: 30 | O24: =SUM(N$4:N24) -> 638 | P24: =SUMIFS('markov model'!M$7:M$3656, 'markov model'!L$7:L$3656,">="&O24,'markov model'!L$7:L$3656,"<"&O25) -> 56.446944 | S24: 4 | T24: =COUNTIF(obsdata,"<"&S24)-SUM(T$20:T23) -> 11 | U24: =COUNTIF(moddata,"<"&S24)-SUM(U$20:U23) -> 137 | W24: 23 | X24: 30.249827 | Y24: 30.249827
M25: 11 | N25: 31 | O25: =SUM(N$4:N25) -> 669 | P25: =SUMIFS('markov model'!M$7:M$3656, 'markov model'!L$7:L$3656,">="&O25,'markov model'!L$7:L$3656,"<"&O26) -> 45.720209 | S25: 5 | T25: =COUNTIF(obsdata,"<"&S25)-SUM(T$20:T24) -> 9 | U25: =COUNTIF(moddata,"<"&S25)-SUM(U$20:U24) -> 91 | W25: 24 | X25: 44.12526 | Y25: 44.12526
M26: 12 | N26: 30 | O26: =SUM(N$4:N26) -> 699 | P26: =SUMIFS('markov model'!M$7:M$3656, 'markov model'!L$7:L$3656,">="&O26,'markov model'!L$7:L$3656,"<"&O27) -> 26.9693 | S26: 6 | T26: =COUNTIF(obsdata,"<"&S26)-SUM(T$20:T25) -> 6 | U26: =COUNTIF(moddata,"<"&S26)-SUM(U$20:U25) -> 49 | W26: 25 | X26: 78.175087 | Y26: 78.175087
I27: Max | M27: 1 | N27: 31 | O27: =SUM(N$4:N27) -> 730 | P27: =SUMIFS('markov model'!M$7:M$3656, 'markov model'!L$7:L$3656,">="&O27,'markov model'!L$7:L$3656,"<"&O28) -> 68.313418 | S27: 7 | T27: =COUNTIF(obsdata,"<"&S27)-SUM(T$20:T26) -> 2 | U27: =COUNTIF(moddata,"<"&S27)-SUM(U$20:U26) -> 29 | W27: 26 | X27: 59.944637 | Y27: 59.944637
I28: Obs | J28: =MAX(obsdata) -> 26.666667 | L28: mm | M28: 2 | N28: 31 | O28: =SUM(N$4:N28) -> 761 | P28: =SUMIFS('markov model'!M$7:M$3656, 'markov model'!L$7:L$3656,">="&O28,'markov model'!L$7:L$3656,"<"&O29) -> 70.844014 | S28: 8 | T28: =COUNTIF(obsdata,"<"&S28)-SUM(T$20:T27) -> 2 | U28: =COUNTIF(moddata,"<"&S28)-SUM(U$20:U27) -> 21 | W28: 27 | X28: 66.731488 | Y28: 66.731488
C29: SD obs | D29: 36.578202 | I29: Model | J29: =MAX(moddata) -> 19.121177 | L29: mm | M29: 3 | N29: 28 | O29: =SUM(N$4:N29) -> 789 | P29: =SUMIFS('markov model'!M$7:M$3656, 'markov model'!L$7:L$3656,">="&O29,'markov model'!L$7:L$3656,"<"&O30) -> 54.741832 | S29: 9 | T29: =COUNTIF(obsdata,"<"&S29)-SUM(T$20:T28) -> 2 | U29: =COUNTIF(moddata,"<"&S29)-SUM(U$20:U28) -> 30 | W29: 28 | X29: 108.1481 | Y29: 108.1481
C30: SD model | D30: =AVERAGE(R3:R14) -> 28.078868 | M30: 4 | N30: 31 | O30: =SUM(N$4:N30) -> 820 | P30: =SUMIFS('markov model'!M$7:M$3656, 'markov model'!L$7:L$3656,">="&O30,'markov model'!L$7:L$3656,"<"&O31) -> 65.732685 | S30: 10 | T30: =COUNTIF(obsdata,"<"&S30)-SUM(T$20:T29) -> 3 | U30: =COUNTIF(moddata,"<"&S30)-SUM(U$20:U29) -> 13 | W30: 29 | X30: 39.444291 | Y30: 39.444291
M31: 5 | N31: 30 | O31: =SUM(N$4:N31) -> 850 | P31: =SUMIFS('markov model'!M$7:M$3656, 'markov model'!L$7:L$3656,">="&O31,'markov model'!L$7:L$3656,"<"&O32) -> 42.571024 | S31: 11 | T31: =COUNTIF(obsdata,"<"&S31)-SUM(T$20:T30) -> 2 | U31: =COUNTIF(moddata,"<"&S31)-SUM(U$20:U30) -> 8 | W31: 30 | X31: 38.088581 | Y31: 38.088581
M32: 6 | N32: 31 | O32: =SUM(N$4:N32) -> 881 | P32: =SUMIFS('markov model'!M$7:M$3656, 'markov model'!L$7:L$3656,">="&O32,'markov model'!L$7:L$3656,"<"&O33) -> 38.202854 | S32: 12 | T32: =COUNTIF(obsdata,"<"&S32)-SUM(T$20:T31) -> 0 | U32: =COUNTIF(moddata,"<"&S32)-SUM(U$20:U31) -> 7 | W32: 31 | X32: 75.505882 | Y32: 75.505882
M33: 7 | N33: 30 | O33: =SUM(N$4:N33) -> 911 | P33: =SUMIFS('markov model'!M$7:M$3656, 'markov model'!L$7:L$3656,">="&O33,'markov model'!L$7:L$3656,"<"&O34) -> 29.729387 | S33: 13 | T33: =COUNTIF(obsdata,"<"&S33)-SUM(T$20:T32) -> 1 | U33: =COUNTIF(moddata,"<"&S33)-SUM(U$20:U32) -> 2 | W33: 32 | X33: 41.489273 | Y33: 41.489273
M34: 8 | N34: 31 | O34: =SUM(N$4:N34) -> 942 | P34: =SUMIFS('markov model'!M$7:M$3656, 'markov model'!L$7:L$3656,">="&O34,'markov model'!L$7:L$3656,"<"&O35) -> 46.407406 | S34: 14 | T34: =COUNTIF(obsdata,"<"&S34)-SUM(T$20:T33) -> 1 | U34: =COUNTIF(moddata,"<"&S34)-SUM(U$20:U33) -> 5 | W34: 33 | X34: 66.323183 | Y34: 66.323183
M35: 9 | N35: 31 | O35: =SUM(N$4:N35) -> 973 | P35: =SUMIFS('markov model'!M$7:M$3656, 'markov model'!L$7:L$3656,">="&O35,'markov model'!L$7:L$3656,"<"&O36) -> 30.008387 | S35: 15 | T35: =COUNTIF(obsdata,"<"&S35)-SUM(T$20:T34) -> 1 | U35: =COUNTIF(moddata,"<"&S35)-SUM(U$20:U34) -> 3 | W35: 34 | X35: 112.95363 | Y35: 112.95363
M36: 10 | N36: 30 | O36: =SUM(N$4:N36) -> 1003 | P36: =SUMIFS('markov model'!M$7:M$3656, 'markov model'!L$7:L$3656,">="&O36,'markov model'!L$7:L$3656,"<"&O37) -> 51.558861 | S36: 16 | T36: =COUNTIF(obsdata,"<"&S36)-SUM(T$20:T35) -> 1 | U36: =COUNTIF(moddata,"<"&S36)-SUM(U$20:U35) -> 3 | W36: 35 | X36: 85.788927 | Y36: 85.788927
M37: 11 | N37: 31 | O37: =SUM(N$4:N37) -> 1034 | P37: =SUMIFS('markov model'!M$7:M$3656, 'markov model'!L$7:L$3656,">="&O37,'markov model'!L$7:L$3656,"<"&O38) -> 56.989119 | S37: 17 | T37: =COUNTIF(obsdata,"<"&S37)-SUM(T$20:T36) -> 0 | U37: =COUNTIF(moddata,"<"&S37)-SUM(U$20:U36) -> 1 | W37: 36 | X37: 47.217301 | Y37: 47.217301
M38: 12 | N38: 30 | O38: =SUM(N$4:N38) -> 1064 | P38: =SUMIFS('markov model'!M$7:M$3656, 'markov model'!L$7:L$3656,">="&O38,'markov model'!L$7:L$3656,"<"&O39) -> 52.719327 | S38: 18 | T38: =COUNTIF(obsdata,"<"&S38)-SUM(T$20:T37) -> 0 | U38: =COUNTIF(moddata,"<"&S38)-SUM(U$20:U37) -> 0 | W38: 37 | X38: 26.391003 | Y38: 26.391003
M39: 1 | N39: 31 | O39: =SUM(N$4:N39) -> 1095 | P39: =SUMIFS('markov model'!M$7:M$3656, 'markov model'!L$7:L$3656,">="&O39,'markov model'!L$7:L$3656,"<"&O40) -> 36.466702 | S39: 19 | T39: =COUNTIF(obsdata,"<"&S39)-SUM(T$20:T38) -> 0 | U39: =COUNTIF(moddata,"<"&S39)-SUM(U$20:U38) -> 0 | W39: 38 | X39: 41.177163 | Y39: 41.177163
M40: 2 | N40: 31 | O40: =SUM(N$4:N40) -> 1126 | P40: =SUMIFS('markov model'!M$7:M$3656, 'markov model'!L$7:L$3656,">="&O40,'markov model'!L$7:L$3656,"<"&O41) -> 50.60768 | S40: 20 | T40: =COUNTIF(obsdata,"<"&S40)-SUM(T$20:T39) -> 0 | U40: =COUNTIF(moddata,"<"&S40)-SUM(U$20:U39) -> 1 | W40: 39 | X40: 108.78685 | Y40: 108.78685
...

Sheet Calc transition matrix
A1: Date | B1: Month cumul | C1: Month | D1: Year | E1: Obs rainfall (mm) | F1: WetOrDry | G1: Sum | H1: code-n | I1: code-t | O1: Codes | V1: transition matrix's for Oct-Jan | Z1: pww | AA1: 0.81 | AB1: 1/lamda=3.1
A2: 39934 | B2: =C2+(D2-2009)*12 -> 5 | C2: 5 | D2: 2009 | E2: 0.73333333 | F2: =IF(E2>0,1,0) -> 1 | G2: =SUM(F2:F2) -> 1 | H2: =IF(G2=1,IF(F1=1,1,-1),G2) -> -1 | I2: =VLOOKUP(H2,codes,2,) -> dw | K2: =COUNTA(E2:E2434) -> 1925 | L2: No of days | O2: -1 | P2: dw | Z2: pdd | AA2: 0.36
A3: 39935 | B3: =C3+(D3-2009)*12 -> 5 | C3: 5 | D3: 2009 | E3: 2.9333333 | F3: =IF(E3>0,1,0) -> 1 | G3: =SUM(F2:F3) -> 2 | H3: =IF(G3=1,IF(F2=1,1,-1),G3) -> 2 | I3: =VLOOKUP(H3,codes,2,) -> ww | K3: =COUNTIF(E2:E2434,">0") -> 1178 | L3: No of wet days | O3: 0 | P3: dd
A4: 39936 | B4: =C4+(D4-2009)*12 -> 5 | C4: 5 | D4: 2009 | E4: 2.3666667 | F4: =IF(E4>0,1,0) -> 1 | G4: =SUM(F3:F4) -> 2 | H4: =IF(G4=1,IF(F3=1,1,-1),G4) -> 2 | I4: =VLOOKUP(H4,codes,2,) -> ww | K4: =COUNTIF(E2:E2434,"=0") -> 747 | L4: No of dry days | O4: 1 | P4: wd | V4: transition matrix's for June-sept | Z4: pww | AA4: 0.73 | AB4: 1/lamda=3.1
A5: 39937 | B5: =C5+(D5-2009)*12 -> 5 | C5: 5 | D5: 2009 | E5: 0.7 | F5: =IF(E5>0,1,0) -> 1 | G5: =SUM(F4:F5) -> 2 | H5: =IF(G5=1,IF(F4=1,1,-1),G5) -> 2 | I5: =VLOOKUP(H5,codes,2,) -> ww | K5: =K3/K2 -> 0.61194805 | L5: Propwet days pwet | O5: 2 | P5: ww | Z5: pdd | AA5: 0.61
A6: 39938 | B6: =C6+(D6-2009)*12 -> 5 | C6: 5 | D6: 2009 | E6: 0.26666667 | F6: =IF(E6>0,1,0) -> 1 | G6: =SUM(F5:F6) -> 2 | H6: =IF(G6=1,IF(F5=1,1,-1),G6) -> 2 | I6: =VLOOKUP(H6,codes,2,) -> ww | K6: =1-K5 -> 0.38805195 | L6: Propdry pdry
A7: 39939 | B7: =C7+(D7-2009)*12 -> 5 | C7: 5 | D7: 2009 | E7: 1 | F7: =IF(E7>0,1,0) -> 1 | G7: =SUM(F6:F7) -> 2 | H7: =IF(G7=1,IF(F6=1,1,-1),G7) -> 2 | I7: =VLOOKUP(H7,codes,2,) -> ww | L7: NB definition of dry is 0.0 mm: all values 0<p<0.2 have been set to 0.0 | V7: transition matrix's for Feb-May | Z7: pww | AA7: 0.77 | AB7: 1/lamda=2.5
A8: 39940 | B8: =C8+(D8-2009)*12 -> 5 | C8: 5 | D8: 2009 | E8: 0.4 | F8: =IF(E8>0,1,0) -> 1 | G8: =SUM(F7:F8) -> 2 | H8: =IF(G8=1,IF(F7=1,1,-1),G8) -> 2 | I8: =VLOOKUP(H8,codes,2,) -> ww | Z8: pdd | AA8: 0.65
A9: 39941 | B9: =C9+(D9-2009)*12 -> 5 | C9: 5 | D9: 2009 | E9: 0.33333333 | F9: =IF(E9>0,1,0) -> 1 | G9: =SUM(F8:F9) -> 2 | H9: =IF(G9=1,IF(F8=1,1,-1),G9) -> 2 | I9: =VLOOKUP(H9,codes,2,) -> ww | K9: =COUNTIF(I$2:I$2434,"=ww")/K3 -> 0.75466893 | L9: pww | M9: Transition matrix | O9: 0.71578445 | P9: pww
A10: 39942 | B10: =C10+(D10-2009)*12 -> 5 | C10: 5 | D10: 2009 | E10: 0.2 | F10: =IF(E10>0,1,0) -> 1 | G10: =SUM(F9:F10) -> 2 | H10: =IF(G10=1,IF(F9=1,1,-1),G10) -> 2 | I10: =VLOOKUP(H10,codes,2,) -> ww | K10: =COUNTIF(I$2:I$2433,"=dd")/(1925-K3) -> 0.61445783 | L10: pdd | O10: 0.61800643 | P10: pdd
A11: 39943 | B11: =C11+(D11-2009)*12 -> 5 | C11: 5 | D11: 2009 | E11: 0.53333333 | F11: =IF(E11>0,1,0) -> 1 | G11: =SUM(F10:F11) -> 2 | H11: =IF(G11=1,IF(F10=1,1,-1),G11) -> 2 | I11: =VLOOKUP(H11,codes,2,) -> ww | K11: =COUNTIF(I$2:I$2434,"=wd")/K3 -> 0.24448217 | L11: pwd | O11: 0.28421555 | P11: pwd
A12: 39944 | B12: =C12+(D12-2009)*12 -> 5 | C12: 5 | D12: 2009 | E12: 0.26666667 | F12: =IF(E12>0,1,0) -> 1 | G12: =SUM(F11:F12) -> 2 | H12: =IF(G12=1,IF(F11=1,1,-1),G12) -> 2 | I12: =VLOOKUP(H12,codes,2,) -> ww | K12: =COUNTIF(I$2:I$2434,"=dw")/(1925-K3) -> 0.38688086 | L12: pdw | O12: 0.38199357 | P12: pdw
A13: 39945 | B13: =C13+(D13-2009)*12 -> 5 | C13: 5 | D13: 2009 | E13: 0 | F13: =IF(E13>0,1,0) -> 0 | G13: =SUM(F12:F13) -> 1 | H13: =IF(G13=1,IF(F12=1,1,-1),G13) -> 1 | I13: =VLOOKUP(H13,codes,2,) -> wd
A14: 39946 | B14: =C14+(D14-2009)*12 -> 5 | C14: 5 | D14: 2009 | E14: 0 | F14: =IF(E14>0,1,0) -> 0 | G14: =SUM(F13:F14) -> 0 | H14: =IF(G14=1,IF(F13=1,1,-1),G14) -> 0 | I14: =VLOOKUP(H14,codes,2,) -> dd
A15: 39947 | B15: =C15+(D15-2009)*12 -> 5 | C15: 5 | D15: 2009 | E15: 0 | F15: =IF(E15>0,1,0) -> 0 | G15: =SUM(F14:F15) -> 0 | H15: =IF(G15=1,IF(F14=1,1,-1),G15) -> 0 | I15: =VLOOKUP(H15,codes,2,) -> dd | K15: =COUNTIF(obsdata,"<0.5") -> 150 | L15: Days less than 0.5 mm | O15: =K15/K$2 -> 0.077922078 | P15: Prop less than 0.5 mm
A16: 39948 | B16: =C16+(D16-2009)*12 -> 5 | C16: 5 | D16: 2009 | E16: 3.1333333 | F16: =IF(E16>0,1,0) -> 1 | G16: =SUM(F15:F16) -> 1 | H16: =IF(G16=1,IF(F15=1,1,-1),G16) -> -1 | I16: =VLOOKUP(H16,codes,2,) -> dw | K16: =COUNTIF(obsdata,"<1.0") -> 164 | L16: Days less than 1.0 mm | O16: =K16/K$2 -> 0.085194805 | P16: Prop less than 1.0 mm
A17: 39949 | B17: =C17+(D17-2009)*12 -> 5 | C17: 5 | D17: 2009 | E17: 8.4 | F17: =IF(E17>0,1,0) -> 1 | G17: =SUM(F16:F17) -> 2 | H17: =IF(G17=1,IF(F16=1,1,-1),G17) -> 2 | I17: =VLOOKUP(H17,codes,2,) -> ww | K17: =COUNTIF(obsdata,"<2.0") -> 188 | L17: Days less than 2.0 mm | O17: =K17/K$2 -> 0.097662338 | P17: Prop less than 2.0 mm
A18: 39950 | B18: =C18+(D18-2009)*12 -> 5 | C18: 5 | D18: 2009 | E18: 3.3333333 | F18: =IF(E18>0,1,0) -> 1 | G18: =SUM(F17:F18) -> 2 | H18: =IF(G18=1,IF(F17=1,1,-1),G18) -> 2 | I18: =VLOOKUP(H18,codes,2,) -> ww | K18: =COUNTIF(obsdata,"<5.0") -> 221 | L18: Days less than 5.0 mm | O18: =K18/K$2 -> 0.11480519 | P18: Prop less than 5.0 mm
A19: 39951 | B19: =C19+(D19-2009)*12 -> 5 | C19: 5 | D19: 2009 | E19: 1.4666667 | F19: =IF(E19>0,1,0) -> 1 | G19: =SUM(F18:F19) -> 2 | H19: =IF(G19=1,IF(F18=1,1,-1),G19) -> 2 | I19: =VLOOKUP(H19,codes,2,) -> ww
A20: 39952 | B20: =C20+(D20-2009)*12 -> 5 | C20: 5 | D20: 2009 | E20: 0.26666667 | F20: =IF(E20>0,1,0) -> 1 | G20: =SUM(F19:F20) -> 2 | H20: =IF(G20=1,IF(F19=1,1,-1),G20) -> 2 | I20: =VLOOKUP(H20,codes,2,) -> ww | K20: Annual rainfall | M20: =SUM(E2:E2434)/15 -> 184.75667 | N20: mm | O20: Original figures
A21: 39953 | B21: =C21+(D21-2009)*12 -> 5 | C21: 5 | D21: 2009 | E21: 2.2333333 | F21: =IF(E21>0,1,0) -> 1 | G21: =SUM(F20:F21) -> 2 | H21: =IF(G21=1,IF(F20=1,1,-1),G21) -> 2 | I21: =VLOOKUP(H21,codes,2,) -> ww | O21: Newbiggin | P21: Harwood | Q21: Font | R21: Wallington | S21: AW | T21: She
A22: 39954 | B22: =C22+(D22-2009)*12 -> 5 | C22: 5 | D22: 2009 | E22: 2.7333333 | F22: =IF(E22>0,1,0) -> 1 | G22: =SUM(F21:F22) -> 2 | H22: =IF(G22=1,IF(F21=1,1,-1),G22) -> 2 | I22: =VLOOKUP(H22,codes,2,) -> ww | O22: 687.46 | P22: 914.7 | Q22: 873.62 | R22: 772.4 | S22: 812.045 | T22: 824.29204
A23: 39955 | B23: =C23+(D23-2009)*12 -> 5 | C23: 5 | D23: 2009 | E23: 0.73333333 | F23: =IF(E23>0,1,0) -> 1 | G23: =SUM(F22:F23) -> 2 | H23: =IF(G23=1,IF(F22=1,1,-1),G23) -> 2 | I23: =VLOOKUP(H23,codes,2,) -> ww | K23: Mean wet day amt | M23: =SUM(E2:E2434)/1178 -> 2.3525891 | N23: mm
A24: 39956 | B24: =C24+(D24-2009)*12 -> 5 | C24: 5 | D24: 2009 | E24: 0.066666667 | F24: =IF(E24>0,1,0) -> 1 | G24: =SUM(F23:F24) -> 2 | H24: =IF(G24=1,IF(F23=1,1,-1),G24) -> 2 | I24: =VLOOKUP(H24,codes,2,) -> ww | K24: For exp model
A25: 39957 | B25: =C25+(D25-2009)*12 -> 5 | C25: 5 | D25: 2009 | E25: 0 | F25: =IF(E25>0,1,0) -> 0 | G25: =SUM(F24:F25) -> 1 | H25: =IF(G25=1,IF(F24=1,1,-1),G25) -> 1 | I25: =VLOOKUP(H25,codes,2,) -> wd
A26: 39958 | B26: =C26+(D26-2009)*12 -> 5 | C26: 5 | D26: 2009 | E26: 0.33333333 | F26: =IF(E26>0,1,0) -> 1 | G26: =SUM(F25:F26) -> 1 | H26: =IF(G26=1,IF(F25=1,1,-1),G26) -> -1 | I26: =VLOOKUP(H26,codes,2,) -> dw
A27: 39959 | B27: =C27+(D27-2009)*12 -> 5 | C27: 5 | D27: 2009 | E27: 0.4 | F27: =IF(E27>0,1,0) -> 1 | G27: =SUM(F26:F27) -> 2 | H27: =IF(G27=1,IF(F26=1,1,-1),G27) -> 2 | I27: =VLOOKUP(H27,codes,2,) -> ww
A28: 39960 | B28: =C28+(D28-2009)*12 -> 5 | C28: 5 | D28: 2009 | E28: 0.2 | F28: =IF(E28>0,1,0) -> 1 | G28: =SUM(F27:F28) -> 2 | H28: =IF(G28=1,IF(F27=1,1,-1),G28) -> 2 | I28: =VLOOKUP(H28,codes,2,) -> ww
A29: 39961 | B29: =C29+(D29-2009)*12 -> 5 | C29: 5 | D29: 2009 | E29: 0 | F29: =IF(E29>0,1,0) -> 0 | G29: =SUM(F28:F29) -> 1 | H29: =IF(G29=1,IF(F28=1,1,-1),G29) -> 1 | I29: =VLOOKUP(H29,codes,2,) -> wd
A30: 39962 | B30: =C30+(D30-2009)*12 -> 5 | C30: 5 | D30: 2009 | E30: 0 | F30: =IF(E30>0,1,0) -> 0 | G30: =SUM(F29:F30) -> 0 | H30: =IF(G30=1,IF(F29=1,1,-1),G30) -> 0 | I30: =VLOOKUP(H30,codes,2,) -> dd
A31: 39963 | B31: =C31+(D31-2009)*12 -> 5 | C31: 5 | D31: 2009 | E31: 0 | F31: =IF(E31>0,1,0) -> 0 | G31: =SUM(F30:F31) -> 0 | H31: =IF(G31=1,IF(F30=1,1,-1),G31) -> 0 | I31: =VLOOKUP(H31,codes,2,) -> dd
A32: 39964 | B32: =C32+(D32-2009)*12 -> 5 | C32: 5 | D32: 2009 | E32: 0 | F32: =IF(E32>0,1,0) -> 0 | G32: =SUM(F31:F32) -> 0 | H32: =IF(G32=1,IF(F31=1,1,-1),G32) -> 0 | I32: =VLOOKUP(H32,codes,2,) -> dd
A33: 40300 | B33: =C33+(D33-2009)*12 -> 17 | C33: 5 | D33: 2010 | E33: 0 | F33: =IF(E33>0,1,0) -> 0 | G33: =SUM(F32:F33) -> 0 | H33: =IF(G33=1,IF(F32=1,1,-1),G33) -> 0 | I33: =VLOOKUP(H33,codes,2,) -> dd
A34: 40301 | B34: =C34+(D34-2009)*12 -> 17 | C34: 5 | D34: 2010 | E34: 0.53333333 | F34: =IF(E34>0,1,0) -> 1 | G34: =SUM(F33:F34) -> 1 | H34: =IF(G34=1,IF(F33=1,1,-1),G34) -> -1 | I34: =VLOOKUP(H34,codes,2,) -> dw
A35: 40302 | B35: =C35+(D35-2009)*12 -> 17 | C35: 5 | D35: 2010 | E35: 0 | F35: =IF(E35>0,1,0) -> 0 | G35: =SUM(F34:F35) -> 1 | H35: =IF(G35=1,IF(F34=1,1,-1),G35) -> 1 | I35: =VLOOKUP(H35,codes,2,) -> wd
A36: 40303 | B36: =C36+(D36-2009)*12 -> 17 | C36: 5 | D36: 2010 | E36: 0.2 | F36: =IF(E36>0,1,0) -> 1 | G36: =SUM(F35:F36) -> 1 | H36: =IF(G36=1,IF(F35=1,1,-1),G36) -> -1 | I36: =VLOOKUP(H36,codes,2,) -> dw
... A1926: 45351 | B1926: =C1926+(D1926-2009)*12 -> 182 | C1926: 2 | D1926: 2024 | E1926: 0.46666667 | F1926: =IF(E1926>0,1,0) -> 1 | G1926: =SUM(F1925:F1926) -> 1 | H1926: =IF(G1926=1,IF(F1925=1,1,-1),G1926) -> -1 | I1926: =VLOOKUP(H1926,codes,2,) -> dw

Sheet Solutions
A2: Markov
A4: The transition matrix should be
A5: Pww | B5: Pwd
A6: Pdw | B6: Pdd | D6: Where rows sum to 1
A8: 0.72 | B8: =1-pww -> 0.25
A9: =1-pdd -> 0.39 | B9: 0.62
A11: This gives a pdry of 0.42 or so, close to the observed 0.43
A13: For amounts: lambda is simply 1/mean.
A14: The mean is the mean daily amount * for wet days*
A15: The number of wet days per year is (1-pdry)*365 = | F15: =(1-0.43)*365 -> 208.05 | G15: days
A16: So mean rain day amount is | D16: 817/208= | E16: =817/F15 -> 3.9269406 | F16: mm
A17: And so lambda = | C17: =1/E16 -> 0.25465116
A19: You can check the mean on the spreadsheet
